<sdf version='1.4'>
  <model name='mkz'>
    <link name='base_footprint'>
      <pose>0 0 0 0 -0 0</pose>
      <inertial>
        <pose>-0.000532907 0 0.580699 0 -0 0</pose>
        <mass>1501.2</mass>
        <inertia>
          <ixx>1001.15</ixx>
          <ixy>0</ixy>
          <ixz>0.695441</ixz>
          <iyy>1001.79</iyy>
          <iyz>0</iyz>
          <izz>1000.9</izz>
        </inertia>
      </inertial>
      <collision name='base_footprint_collision_base_link'>
        <pose>0.084967 -0.03046 0.680609 1.5708 -0 3.14159</pose>
        <geometry>
          <mesh>
            <scale>0.001 0.001 0.001</scale>
            <uri>model://dbw_mkz_description/meshes/body_collision.stl</uri>
          </mesh>
        </geometry>
        <surface>
          <contact>
            <ode/>
          </contact>
          <friction>
            <ode>
              <mu>0.5</mu>
              <mu2>0.5</mu2>
            </ode>
          </friction>
        </surface>
      </collision>
      <visual name='base_footprint_visual_base_link'>
        <pose>-0.058415 0 0 0 -0 1.5708</pose>
        <geometry>
          <mesh>
            <scale>0.394 0.394 0.394</scale>
            <uri>file:///opt/ros/indigo/share/dbw_mkz_description/meshes/mkz_13/body.dae</uri>
          </mesh>
        </geometry>
      </visual>
      <velocity_decay>
        <linear>0</linear>
        <angular>0</angular>
      </velocity_decay>
      <velocity_decay>
        <linear>0</linear>
        <angular>0</angular>
      </velocity_decay>
      <gravity>1</gravity>
      <velocity_decay>
        <linear>0</linear>
        <angular>0</angular>
      </velocity_decay>
      <self_collide>0</self_collide>
    </link>
    
    <link name='steer_fl'>
      <pose>1.43505 0.817 0.66 0 -0 0</pose>
      <inertial>
        <pose>-0.013054 -0.0295 0 0 -0 0</pose>
        <mass>1</mass>
        <inertia>
          <ixx>0.037227</ixx>
          <ixy>0</ixy>
          <ixz>0</ixz>
          <iyy>0.04</iyy>
          <iyz>0</iyz>
          <izz>0.06</izz>
        </inertia>
      </inertial>
      <velocity_decay>
        <linear>0</linear>
        <angular>0</angular>
      </velocity_decay>
    </link>
    <joint name='steer_fl' type='revolute'>
      <child>steer_fl</child>
      <parent>base_footprint</parent>
      <axis>
        <xyz>0 0 1</xyz>
        <limit>
          <lower>-0.6</lower>
          <upper>0.6</upper>
          <effort>0</effort>
          <velocity>0</velocity>
        </limit>
        <dynamics/>
      </axis>
    </joint>
    <link name='wheel_fl'>
      <pose>1.4224 0.7875 0.33 1.5708 -0 3.14159</pose>
      <inertial>
        <pose>0 0 0 -3.14159 3.4641e-07 -3.14159</pose>
        <mass>10</mass>
        <inertia>
          <ixx>0.305583</ixx>
          <ixy>0</ixy>
          <ixz>0</ixz>
          <iyy>0.305583</iyy>
          <iyz>0</iyz>
          <izz>0.5445</izz>
        </inertia>
      </inertial>
      <collision name='wheel_fl_collision'>
        <pose>0 0 0 -3.14159 3.4641e-07 -3.14159</pose>
        <geometry>
          <cylinder>
            <length>0.2</length>
            <radius>0.33</radius>
          </cylinder>
        </geometry>
        <surface>
          <contact>
            <ode/>
          </contact>
          <friction>
            <ode>
              <mu>1.2</mu>
              <mu2>1.2</mu2>
            </ode>
          </friction>
        </surface>
      </collision>
      <visual name='wheel_fl_visual'>
        <pose>0 0 0.0385 1.57079 -1.57079 3.14159</pose>
        <geometry>
          <mesh>
            <scale>0.01 0.01 0.01</scale>
            <uri>model://dbw_mkz_description/meshes/mkz_13/wheel.dae</uri>
          </mesh>
        </geometry>
      </visual>
      <gravity>1</gravity>
      <velocity_decay>
        <linear>0</linear>
        <angular>0</angular>
      </velocity_decay>
      <self_collide>0</self_collide>
    </link>
    <joint name='wheel_fl' type='revolute'>
      <child>wheel_fl</child>
      <parent>steer_fl</parent>
      <axis>
        <xyz>3.4641e-07 1 3.26795e-07</xyz>
        <limit>
          <lower>-1e+16</lower>
          <upper>1e+16</upper>
        </limit>
        <dynamics/>
      </axis>
      <physics>
        <ode>
          <limit>
            <cfm>0</cfm>
            <erp>0.2</erp>
          </limit>
        </ode>
      </physics>
    </joint>
    <link name='steer_fr'>
      <pose>1.43505 -0.815 0.66 0 -0 0</pose>
      <inertial>
        <pose>-0.01305 0.0275 0 0 -0 0</pose>
        <mass>1</mass>
        <inertia>
          <ixx>0.037227</ixx>
          <ixy>0</ixy>
          <ixz>0</ixz>
          <iyy>0.04</iyy>
          <iyz>0</iyz>
          <izz>0.06</izz>
        </inertia>
      </inertial>
      <velocity_decay>
        <linear>0</linear>
        <angular>0</angular>
      </velocity_decay>
    </link>
    <joint name='steer_fr' type='revolute'>
      <child>steer_fr</child>
      <parent>base_footprint</parent>
      <axis>
        <xyz>0 0 1</xyz>
        <limit>
          <lower>-0.6</lower>
          <upper>0.6</upper>
          <effort>0</effort>
          <velocity>0</velocity>
        </limit>
        <dynamics/>
      </axis>
    </joint>
    <link name='wheel_fr'>
      <pose>1.4224 -0.7875 0.33 1.5708 -0 3.14159</pose>
      <inertial>
        <pose>0 0 0 3.14159 -3.4641e-07 3.14159</pose>
        <mass>10</mass>
        <inertia>
          <ixx>0.305583</ixx>
          <ixy>0</ixy>
          <ixz>0</ixz>
          <iyy>0.305583</iyy>
          <iyz>0</iyz>
          <izz>0.5445</izz>
        </inertia>
      </inertial>
      <collision name='wheel_fr_collision'>
        <pose>0 0 -0.0035 3.14159 -3.4641e-07 3.14159</pose>
        <geometry>
          <cylinder>
            <length>0.2</length>
            <radius>0.33</radius>
          </cylinder>
        </geometry>
        <surface>
          <contact>
            <ode/>
          </contact>
          <friction>
            <ode>
              <mu>1.2</mu>
              <mu2>1.2</mu2>
            </ode>
          </friction>
        </surface>
      </collision>
      <visual name='wheel_fr_visual'>
        <pose>0 0 -0.043777 1.57079 1.57079 3.14159</pose>
        <geometry>
          <mesh>
            <scale>0.01 0.01 0.01</scale>
            <uri>model://dbw_mkz_description/meshes/mkz_13/wheel.dae</uri>
          </mesh>
        </geometry>
      </visual>
      <gravity>1</gravity>
      <velocity_decay>
        <linear>0</linear>
        <angular>0</angular>
      </velocity_decay>
      <self_collide>0</self_collide>
    </link>
    <joint name='wheel_fr' type='revolute'>
      <child>wheel_fr</child>
      <parent>steer_fr</parent>
      <axis>
        <xyz>3.4641e-07 1 3.26795e-07</xyz>
        <limit>
          <lower>-1e+16</lower>
          <upper>1e+16</upper>
        </limit>
        <dynamics/>
      </axis>
      <physics>
        <ode>
          <limit>
            <cfm>0</cfm>
            <erp>0.2</erp>
          </limit>
        </ode>
      </physics>
    </joint>
    <link name='wheel_rl'>
      <pose>-1.4224 0.808618 0.33 1.5708 -0 3.14159</pose>
      <inertial>
        <pose>0 0 -0.021117 3.14159 -3.4641e-07 3.14159</pose>
        <mass>10</mass>
        <inertia>
          <ixx>0.305583</ixx>
          <ixy>0</ixy>
          <ixz>0</ixz>
          <iyy>0.305583</iyy>
          <iyz>0</iyz>
          <izz>0.5445</izz>
        </inertia>
      </inertial>
      <collision name='wheel_rl_collision'>
        <pose>0 0 -0.021118 3.14159 -3.4641e-07 3.14159</pose>
        <geometry>
          <cylinder>
            <length>0.2</length>
            <radius>0.33</radius>
          </cylinder>
        </geometry>
        <surface>
          <contact>
            <ode/>
          </contact>
          <friction>
            <ode>
              <mu>1.2</mu>
              <mu2>1.2</mu2>
            </ode>
          </friction>
        </surface>
      </collision>
      <visual name='wheel_rl_visual'>
        <pose>0 0 0.017382 1.57079 -1.57079 3.14159</pose>
        <geometry>
          <mesh>
            <scale>0.01 0.01 0.01</scale>
            <uri>model://dbw_mkz_description/meshes/mkz_13/wheel.dae</uri>
          </mesh>
        </geometry>
      </visual>
      <gravity>1</gravity>
      <velocity_decay>
        <linear>0</linear>
        <angular>0</angular>
      </velocity_decay>
      <self_collide>0</self_collide>
    </link>
    <joint name='wheel_rl' type='revolute'>
      <child>wheel_rl</child>
      <parent>base_footprint</parent>
      <axis>
        <xyz>3.4641e-07 1 3.26795e-07</xyz>
        <limit>
          <lower>-1e+16</lower>
          <upper>1e+16</upper>
        </limit>
        <dynamics/>
      </axis>
      <physics>
        <ode>
          <limit>
            <cfm>0</cfm>
            <erp>0.2</erp>
          </limit>
        </ode>
      </physics>
    </joint>
    <link name='wheel_rr'>
      <pose>-1.4224 -0.808 0.33 1.5708 -0 3.14159</pose>
      <inertial>
        <pose>0 0 0.0205 3.14159 -3.4641e-07 3.14159</pose>
        <mass>10</mass>
        <inertia>
          <ixx>0.305583</ixx>
          <ixy>0</ixy>
          <ixz>0</ixz>
          <iyy>0.305583</iyy>
          <iyz>0</iyz>
          <izz>0.5445</izz>
        </inertia>
      </inertial>
      <collision name='wheel_rr_collision'>
        <pose>0 0 0.0205 3.14159 -3.4641e-07 3.14159</pose>
        <geometry>
          <cylinder>
            <length>0.2</length>
            <radius>0.33</radius>
          </cylinder>
        </geometry>
        <surface>
          <contact>
            <ode/>
          </contact>
          <friction>
            <ode>
              <mu>1.2</mu>
              <mu2>1.2</mu2>
            </ode>
          </friction>
        </surface>
      </collision>
      <visual name='wheel_rr_visual'>
        <pose>0 0 -0.019214 1.57079 1.57079 3.14159</pose>
        <geometry>
          <mesh>
            <scale>0.01 0.01 0.01</scale>
            <uri>model://dbw_mkz_description/meshes/mkz_13/wheel.dae</uri>
          </mesh>
        </geometry>
      </visual>
      <gravity>1</gravity>
      <velocity_decay>
        <linear>0</linear>
        <angular>0</angular>
      </velocity_decay>
      <self_collide>0</self_collide>
    </link>
    <joint name='wheel_rr' type='revolute'>
      <child>wheel_rr</child>
      <parent>base_footprint</parent>
      <axis>
        <xyz>3.4641e-07 1 3.26795e-07</xyz>
        <limit>
          <lower>-1e+16</lower>
          <upper>1e+16</upper>
        </limit>
        <dynamics/>
      </axis>
      <physics>
        <ode>
          <limit>
            <cfm>0</cfm>
            <erp>0.2</erp>
          </limit>
        </ode>
      </physics>
    </joint>
  </model>
</sdf>
