<robot
  name="mercedes">
  <link
    name="base_link">
    <inertial>
      <origin
        xyz="-0.022756 -0.00070119 -0.16882"
        rpy="0 0 0" />
      <mass
        value="0.46994" />
      <inertia
        ixx="0.019711"
        ixy="-9.4374E-05"
        ixz="-0.23434"
        iyy="2.8911"
        iyz="-7.911E-06"
        izz="2.8714" />
    </inertial>
    <visual>
      <origin
        xyz="0 0 0"
        rpy="0 0 0" />
      <geometry>
        <mesh
          filename="package://mercedes/meshes/base_link.STL" />
      </geometry>
      <material
        name="">
        <color
          rgba="1 1 1 1" />
      </material>
    </visual>
    <collision>
      <origin
        xyz="0 0 0"
        rpy="0 0 0" />
      <geometry>
        <mesh
          filename="package://mercedes/meshes/base_link.STL" />
      </geometry>
    </collision>
  </link>
  <link
    name="fwr">
    <inertial>
      <origin
        xyz="-1.6795 0.81799 -0.47744"
        rpy="0 0 0" />
      <mass
        value="18.518" />
      <inertia
        ixx="0.0063448"
        ixy="-0.0016896"
        ixz="-0.0017342"
        iyy="0.0073613"
        iyz="-0.00042336"
        izz="0.012824" />
    </inertial>
    <visual>
      <origin
        xyz="0 0 0"
        rpy="0 0 0" />
      <geometry>
        <mesh
          filename="package://mercedes/meshes/fwr.STL" />
      </geometry>
      <material
        name="">
        <color
          rgba="0.79216 0.81961 0.93333 1" />
      </material>
    </visual>
    <collision>
      <origin
        xyz="0 0 0"
        rpy="0 0 0" />
      <geometry>
        <mesh
          filename="package://mercedes/meshes/fwr.STL" />
      </geometry>
    </collision>
  </link>
  <joint
    name="fwr"
    type="continuous">
    <origin
      xyz="0 0 0"
      rpy="0 0 0" />
    <parent
      link="base_link" />
    <child
      link="fwr" />
    <axis
      xyz="0 -1 0" />
  </joint>
  <link
    name="fwl">
    <inertial>
      <origin
        xyz="-1.679495721854 -0.819230283138361 -0.477430986197705"
        rpy="0 0 0" />
      <mass
        value="18.5176274523984" />
      <inertia
        ixx="0.00636194279569933"
        ixy="0.00168734652676502"
        ixz="-0.001765955052283"
        iyy="0.00736137905740598"
        iyz="0.000432474595772037"
        izz="0.0128067389927221" />
    </inertial>
    <visual>
      <origin
        xyz="0 0 0"
        rpy="0 0 0" />
      <geometry>
        <mesh
          filename="package://mercedes/meshes/fwl.STL" />
      </geometry>
      <material
        name="">
        <color
          rgba="0.792156862745098 0.819607843137255 0.933333333333333 1" />
      </material>
    </visual>
    <collision>
      <origin
        xyz="0 0 0"
        rpy="0 0 0" />
      <geometry>
        <mesh
          filename="package://mercedes/meshes/fwl.STL" />
      </geometry>
    </collision>
  </link>
  <joint
    name="fwl"
    type="continuous">
    <origin
      xyz="0 0 0"
      rpy="0 0 0" />
    <parent
      link="base_link" />
    <child
      link="fwl" />
    <axis
      xyz="0 -1 0" />
  </joint>
  <link
    name="rwr">
    <inertial>
      <origin
        xyz="1.35068012394788 -0.819230281010398 -0.476823818624177"
        rpy="0 0 0" />
      <mass
        value="18.5176283437402" />
      <inertia
        ixx="0.00744638881272935"
        ixy="0.00154895947081522"
        ixz="-0.00298859647759909"
        iyy="0.00736145911947223"
        iyz="0.000796883459145383"
        izz="0.0117223831818257" />
    </inertial>
    <visual>
      <origin
        xyz="0 0 0"
        rpy="0 0 0" />
      <geometry>
        <mesh
          filename="package://mercedes/meshes/rwr.STL" />
      </geometry>
      <material
        name="">
        <color
          rgba="0.792156862745098 0.819607843137255 0.933333333333333 1" />
      </material>
    </visual>
    <collision>
      <origin
        xyz="0 0 0"
        rpy="0 0 0" />
      <geometry>
        <mesh
          filename="package://mercedes/meshes/rwr.STL" />
      </geometry>
    </collision>
  </link>
  <joint
    name="rwr"
    type="continuous">
    <origin
      xyz="0 0 0"
      rpy="0 0 0" />
    <parent
      link="base_link" />
    <child
      link="rwr" />
    <axis
      xyz="0 -1 0" />
  </joint>
  <link
    name="rwl">
    <inertial>
      <origin
        xyz="1.3506828944589 0.817986562486695 -0.476829356487747"
        rpy="0 0 0" />
      <mass
        value="18.5176264794013" />
      <inertia
        ixx="0.00742395272283717"
        ixy="-0.00155232104240781"
        ixz="-0.00297241854192936"
        iyy="0.00736143359548626"
        iyz="-0.000790279348357291"
        izz="0.0117447744343887" />
    </inertial>
    <visual>
      <origin
        xyz="0 0 0"
        rpy="0 0 0" />
      <geometry>
        <mesh
          filename="package://mercedes/meshes/rwl.STL" />
      </geometry>
      <material
        name="">
        <color
          rgba="0.792156862745098 0.819607843137255 0.933333333333333 1" />
      </material>
    </visual>
    <collision>
      <origin
        xyz="0 0 0"
        rpy="0 0 0" />
      <geometry>
        <mesh
          filename="package://mercedes/meshes/rwl.STL" />
      </geometry>
    </collision>
  </link>
  <joint
    name="rwl"
    type="continuous">
    <origin
      xyz="0 0 0"
      rpy="0 0 0" />
    <parent
      link="base_link" />
    <child
      link="rwl" />
    <axis
      xyz="0 -1 0" />
  </joint>
</robot>
