<sdf version='1.4'>
  <model name='all_in_one'>
    <link name='base_link'>
      <pose>0 0 0 0 -0 0</pose>
      <inertial>
        <pose>1.05 0 0.4039 0 -0 0</pose>
        <mass>2050</mass>
        <inertia>
          <ixx>63.0001</ixx>
          <ixy>0</ixy>
          <ixz>-31</ixz>
          <iyy>1048</iyy>
          <iyz>0</iyz>
          <izz>1111</izz>
        </inertia>
      </inertial>
      <collision name='base_link_collision'>
        <pose>1.31 0 0.7639 0 -0 0</pose>
        <geometry>
          <box>
            <size>3.8 1.301 0.8</size>
          </box>
        </geometry>
      </collision>
      <collision name='base_link_collision_camera_link'>
        <pose>1.31 0 1.966 0 -0 0</pose>
        <geometry>
          <box>
            <size>0.25 0.25 0.25</size>
          </box>
        </geometry>
      </collision>
      <collision name='base_link_collision_front_laser_link'>
        <pose>3.6 0 0.476 0 -0 0</pose>
        <geometry>
          <box>
            <size>0.25 0.25 0.25</size>
          </box>
        </geometry>
        <surface>
          <contact>
            <ode/>
          </contact>
          <friction>
            <ode>
              <mu>0.6</mu>
              <mu2>0.5</mu2>
            </ode>
          </friction>
        </surface>
        <surface>
          <contact>
            <ode/>
          </contact>
          <friction>
            <ode/>
          </friction>
        </surface>
      </collision>
      <collision name='base_link_collision_laser_link'>
        <pose>1.31 0 2.101 0 -0 0</pose>
        <geometry>
          <box>
            <size>0.25 0.25 0.25</size>
          </box>
        </geometry>
        <surface>
          <contact>
            <ode/>
          </contact>
          <friction>
            <ode>
              <mu>0.6</mu>
              <mu2>0.5</mu2>
            </ode>
          </friction>
        </surface>
        <surface>
          <contact>
            <ode/>
          </contact>
          <friction>
            <ode/>
          </friction>
        </surface>
      </collision>
      <visual name='base_link_visual'>
        <pose>1.06 0 0.7949 0 -0 0</pose>
        <geometry>
          <mesh>
            <scale>1 1 1</scale>
            <uri>model://all_in_one/meshes/ford_escape_no_wheels_2.dae</uri>
          </mesh>
        </geometry>
      </visual>
      <visual name='base_link_visual_camera_link'>
        <pose>1.31 0 1.966 0 -0 0</pose>
        <geometry>
          <box>
            <size>0.25 0.25 0.25</size>
          </box>
        </geometry>
      </visual>
      <visual name='base_link_visual_front_laser_link'>
        <pose>3.6 0 0.476 0 -0 0</pose>
        <geometry>
          <box>
            <size>0.25 0.25 0.25</size>
          </box>
        </geometry>
      </visual>
      <visual name='base_link_visual_laser_link'>
        <pose>1.31 0 2.101 0 -0 0</pose>
        <geometry>
          <mesh>
            <scale>1 1 1</scale>
            <uri>model://all_in_one/meshes/hokuyo.dae</uri>
          </mesh>
        </geometry>
      </visual>
      <velocity_decay>
        <linear>0</linear>
        <angular>0</angular>
      </velocity_decay>
      <velocity_decay>
        <linear>0</linear>
        <angular>0</angular>
      </velocity_decay>
      <sensor name='lidar_sensor' type='ray'>
        <visualize>0</visualize>
        <update_rate>5</update_rate>
        <ray>
          <scan>
            <horizontal>
              <samples>300</samples>
              <resolution>1</resolution>
              <min_angle>-3.14</min_angle>
              <max_angle>3.14</max_angle>
            </horizontal>
            <vertical>
              <samples>20</samples>
              <resolution>1</resolution>
              <min_angle>-0.0349066</min_angle>
              <max_angle>0.326</max_angle>
            </vertical>
          </scan>
          <range>
            <min>1</min>
            <max>50</max>
            <resolution>0.02</resolution>
          </range>
        </ray>
        <plugin name='laser_controller' filename='libgazebo_ros_block_laser.so'>
          <frameName>laser_link</frameName>
          <hokuyoMinIntensity>101</hokuyoMinIntensity>
          <robotNamespace>/all_in_one</robotNamespace>
          <topicName>lidar_points</topicName>
          <gaussianNoise>0.02</gaussianNoise>
          <updateRate>5</updateRate>
        </plugin>
        <pose>1.31 0 2.101 0 -0 0</pose>
      </sensor>
      <velocity_decay>
        <linear>0</linear>
        <angular>0</angular>
      </velocity_decay>
      <gravity>1</gravity>
      <velocity_decay>
        <linear>0</linear>
        <angular>0</angular>
      </velocity_decay>
      <self_collide>0</self_collide>
      <sensor name='sick_lms291' type='ray'>
        <visualize>1</visualize>
        <update_rate>50</update_rate>
        <ray>
          <scan>
            <horizontal>
              <samples>180</samples>
              <resolution>1</resolution>
              <min_angle>-1.57</min_angle>
              <max_angle>1.57</max_angle>
            </horizontal>
          </scan>
          <range>
            <min>1.5</min>
            <max>50</max>
            <resolution>0.05</resolution>
          </range>
        </ray>
        <plugin name='sick_lms291_controller' filename='libgazebo_ros_laser.so'>
          <topicName>/all_in_one/front_laser_points</topicName>
          <frameName>front_laser_link</frameName>
          <gaussianNoise>0.02</gaussianNoise>
        </plugin>
        <pose>3.6 0 0.476 0 -0 0</pose>
      </sensor>
    </link>
    <link name='back_left_wheel_link'>
      <pose>0 0.765 0.319 0 -0 0</pose>
      <inertial>
        <pose>0 0 0 0 -0 0</pose>
        <mass>40</mass>
        <inertia>
          <ixx>54</ixx>
          <ixy>0</ixy>
          <ixz>0</ixz>
          <iyy>56</iyy>
          <iyz>0</iyz>
          <izz>104</izz>
        </inertia>
      </inertial>
      <collision name='back_left_wheel_link_collision'>
        <pose>0 0 0 1.5708 -0 0</pose>
        <geometry>
          <cylinder>
            <length>0.229</length>
            <radius>0.356</radius>
          </cylinder>
        </geometry>
        <surface>
          <contact>
            <ode>
              <kp>1e+07</kp>
              <kd>1</kd>
              <max_vel>10</max_vel>
              <min_depth>0.01</min_depth>
            </ode>
          </contact>
          <friction>
            <ode>
              <mu>10000</mu>
              <mu2>10000</mu2>
            </ode>
          </friction>
        </surface>
      </collision>
      <visual name='back_left_wheel_link_visual'>
        <pose>0 0 0 0 -0 1.5708</pose>
        <geometry>
          <mesh>
            <scale>1 1 1</scale>
            <uri>model://all_in_one/meshes/ford_escape_wheel.dae</uri>
          </mesh>
        </geometry>
      </visual>
      <gravity>1</gravity>
      <velocity_decay>
        <linear>0</linear>
        <angular>0</angular>
      </velocity_decay>
      <self_collide>0</self_collide>
    </link>
    <joint name='back_left_wheel_joint' type='revolute'>
      <child>back_left_wheel_link</child>
      <parent>base_link</parent>
      <axis>
        <xyz>0 1 0</xyz>
        <limit>
          <lower>-1e+16</lower>
          <upper>1e+16</upper>
        </limit>
        <dynamics>
          <damping>0.1</damping>
        </dynamics>
      </axis>
    </joint>
    <link name='back_right_wheel_link'>
      <pose>0 -0.765 0.319 0 -0 0</pose>
      <inertial>
        <pose>0 0 0 0 -0 0</pose>
        <mass>40</mass>
        <inertia>
          <ixx>54</ixx>
          <ixy>0</ixy>
          <ixz>0</ixz>
          <iyy>56</iyy>
          <iyz>0</iyz>
          <izz>104</izz>
        </inertia>
      </inertial>
      <collision name='back_right_wheel_link_collision'>
        <pose>0 0 0 1.5708 -0 0</pose>
        <geometry>
          <cylinder>
            <length>0.229</length>
            <radius>0.356</radius>
          </cylinder>
        </geometry>
        <surface>
          <contact>
            <ode>
              <kp>1e+07</kp>
              <kd>1</kd>
              <max_vel>10</max_vel>
              <min_depth>0.01</min_depth>
            </ode>
          </contact>
          <friction>
            <ode>
              <mu>10000</mu>
              <mu2>10000</mu2>
            </ode>
          </friction>
        </surface>
      </collision>
      <visual name='back_right_wheel_link_visual'>
        <pose>0 0 0 0 0 -1.5708</pose>
        <geometry>
          <mesh>
            <scale>1 1 1</scale>
            <uri>model://all_in_one/meshes/ford_escape_wheel.dae</uri>
          </mesh>
        </geometry>
      </visual>
      <gravity>1</gravity>
      <velocity_decay>
        <linear>0</linear>
        <angular>0</angular>
      </velocity_decay>
      <self_collide>0</self_collide>
    </link>
    <joint name='back_right_wheel_joint' type='revolute'>
      <child>back_right_wheel_link</child>
      <parent>base_link</parent>
      <axis>
        <xyz>0 1 0</xyz>
        <limit>
          <lower>-1e+16</lower>
          <upper>1e+16</upper>
        </limit>
        <dynamics>
          <damping>0.1</damping>
        </dynamics>
      </axis>
    </joint>
    <link name='front_left_steering_link'>
      <pose>2.62 0.6555 0.319 0 -0 0</pose>
      <inertial>
        <pose>0 0 0 0 -0 0</pose>
        <mass>10</mass>
        <inertia>
          <ixx>0.4</ixx>
          <ixy>0</ixy>
          <ixz>0</ixz>
          <iyy>0.6</iyy>
          <iyz>0</iyz>
          <izz>0.4</izz>
        </inertia>
      </inertial>
      <collision name='front_left_steering_link_collision'>
        <pose>0 0 0 1.5708 -0 0</pose>
        <geometry>
          <cylinder>
            <length>0.01</length>
            <radius>0.1</radius>
          </cylinder>
        </geometry>
        <surface>
          <contact>
            <ode>
              <kp>1e+06</kp>
              <kd>0.1</kd>
              <max_vel>10</max_vel>
              <min_depth>0.01</min_depth>
            </ode>
          </contact>
          <friction>
            <ode>
              <mu>0.6</mu>
              <mu2>0.5</mu2>
            </ode>
          </friction>
        </surface>
      </collision>
      <visual name='front_left_steering_link_visual'>
        <pose>0 0 0 1.5708 -0 0</pose>
        <geometry>
          <cylinder>
            <length>0.01</length>
            <radius>0.1</radius>
          </cylinder>
        </geometry>
      </visual>
      <gravity>1</gravity>
      <velocity_decay>
        <linear>0</linear>
        <angular>0</angular>
      </velocity_decay>
      <self_collide>0</self_collide>
    </link>
    <joint name='front_left_steering_joint' type='revolute'>
      <child>front_left_steering_link</child>
      <parent>base_link</parent>
      <axis>
        <xyz>0 0 1</xyz>
        <limit>
          <lower>-0.6</lower>
          <upper>0.6</upper>
          <effort>1000</effort>
          <velocity>0.5</velocity>
        </limit>
        <dynamics/>
      </axis>
    </joint>
    <link name='front_left_wheel_link'>
      <pose>2.62 0.775 0.319 0 -0 0</pose>
      <inertial>
        <pose>0 0 0 0 -0 0</pose>
        <mass>40</mass>
        <inertia>
          <ixx>54</ixx>
          <ixy>0</ixy>
          <ixz>0</ixz>
          <iyy>56</iyy>
          <iyz>0</iyz>
          <izz>104</izz>
        </inertia>
      </inertial>
      <collision name='front_left_wheel_link_collision'>
        <pose>0 0 0 1.5708 -0 0</pose>
        <geometry>
          <cylinder>
            <length>0.229</length>
            <radius>0.356</radius>
          </cylinder>
        </geometry>
        <surface>
          <contact>
            <ode>
              <kp>1e+06</kp>
              <kd>1</kd>
              <max_vel>100</max_vel>
              <min_depth>0.01</min_depth>
            </ode>
          </contact>
          <friction>
            <ode>
              <mu>10000</mu>
              <mu2>10000</mu2>
            </ode>
          </friction>
        </surface>
      </collision>
      <visual name='front_left_wheel_link_visual'>
        <pose>0 0 0 0 -0 1.5708</pose>
        <geometry>
          <mesh>
            <scale>1 1 1</scale>
            <uri>model://all_in_one/meshes/ford_escape_wheel.dae</uri>
          </mesh>
        </geometry>
      </visual>
      <gravity>1</gravity>
      <velocity_decay>
        <linear>0</linear>
        <angular>0</angular>
      </velocity_decay>
      <self_collide>0</self_collide>
    </link>
    <joint name='front_left_wheel_joint' type='revolute'>
      <child>front_left_wheel_link</child>
      <parent>front_left_steering_link</parent>
      <axis>
        <xyz>0 1 0</xyz>
        <limit>
          <lower>-1e+16</lower>
          <upper>1e+16</upper>
        </limit>
        <dynamics>
          <damping>0.1</damping>
        </dynamics>
      </axis>
    </joint>
    <link name='front_right_steering_link'>
      <pose>2.62 -0.6555 0.319 0 -0 0</pose>
      <inertial>
        <pose>0 0 0 0 -0 0</pose>
        <mass>10</mass>
        <inertia>
          <ixx>0.4</ixx>
          <ixy>0</ixy>
          <ixz>0</ixz>
          <iyy>0.6</iyy>
          <iyz>0</iyz>
          <izz>0.4</izz>
        </inertia>
      </inertial>
      <collision name='front_right_steering_link_collision'>
        <pose>0 0 0 1.5708 -0 0</pose>
        <geometry>
          <cylinder>
            <length>0.01</length>
            <radius>0.1</radius>
          </cylinder>
        </geometry>
        <surface>
          <contact>
            <ode>
              <kp>1e+06</kp>
              <kd>0.1</kd>
              <max_vel>10</max_vel>
              <min_depth>0.01</min_depth>
            </ode>
          </contact>
          <friction>
            <ode>
              <mu>0.6</mu>
              <mu2>0.5</mu2>
            </ode>
          </friction>
        </surface>
      </collision>
      <visual name='front_right_steering_link_visual'>
        <pose>0 0 0 1.5708 -0 0</pose>
        <geometry>
          <cylinder>
            <length>0.01</length>
            <radius>0.1</radius>
          </cylinder>
        </geometry>
      </visual>
      <gravity>1</gravity>
      <velocity_decay>
        <linear>0</linear>
        <angular>0</angular>
      </velocity_decay>
      <self_collide>0</self_collide>
    </link>
    <joint name='front_right_steering_joint' type='revolute'>
      <child>front_right_steering_link</child>
      <parent>base_link</parent>
      <axis>
        <xyz>0 0 1</xyz>
        <limit>
          <lower>-0.6</lower>
          <upper>0.6</upper>
          <effort>1000</effort>
          <velocity>0.5</velocity>
        </limit>
        <dynamics/>
      </axis>
    </joint>
    <link name='front_right_wheel_link'>
      <pose>2.62 -0.775 0.319 0 -0 0</pose>
      <inertial>
        <pose>0 0 0 0 -0 0</pose>
        <mass>40</mass>
        <inertia>
          <ixx>54</ixx>
          <ixy>0</ixy>
          <ixz>0</ixz>
          <iyy>56</iyy>
          <iyz>0</iyz>
          <izz>104</izz>
        </inertia>
      </inertial>
      <collision name='front_right_wheel_link_collision'>
        <pose>0 0 0 1.5708 -0 0</pose>
        <geometry>
          <cylinder>
            <length>0.229</length>
            <radius>0.356</radius>
          </cylinder>
        </geometry>
        <surface>
          <contact>
            <ode>
              <kp>1e+06</kp>
              <kd>1</kd>
              <max_vel>100</max_vel>
              <min_depth>0.01</min_depth>
            </ode>
          </contact>
          <friction>
            <ode>
              <mu>10000</mu>
              <mu2>10000</mu2>
            </ode>
          </friction>
        </surface>
      </collision>
      <visual name='front_right_wheel_link_visual'>
        <pose>0 0 0 0 0 -1.5708</pose>
        <geometry>
          <mesh>
            <scale>1 1 1</scale>
            <uri>model://all_in_one/meshes/ford_escape_wheel.dae</uri>
          </mesh>
        </geometry>
      </visual>
      <gravity>1</gravity>
      <velocity_decay>
        <linear>0</linear>
        <angular>0</angular>
      </velocity_decay>
      <self_collide>0</self_collide>
    </link>
    <joint name='front_right_wheel_joint' type='revolute'>
      <child>front_right_wheel_link</child>
      <parent>front_right_steering_link</parent>
      <axis>
        <xyz>0 1 0</xyz>
        <limit>
          <lower>-1e+16</lower>
          <upper>1e+16</upper>
        </limit>
        <dynamics/>
      </axis>
    </joint>
    <plugin name='gazebo_ros_control' filename='libgazebo_ros_control.so'>
      <robotNamespace>/all_in_one</robotNamespace>
      <robotSimType>gazebo_ros_control/DefaultRobotHWSim</robotSimType>
    </plugin>
    <plugin name='joint_state_publisher' filename='libgazebo_ros_joint_state_publisher.so'>
      <jointName>back_left_wheel_joint, back_right_wheel_joint, front_left_steering_joint, front_right_steering_joint, front_right_wheel_joint, front_left_wheel_joint</jointName>
      <updateRate>50.0</updateRate>
      <robotNamespace>/all_in_one</robotNamespace>
      <alwaysOn>true</alwaysOn>
    </plugin>
    <static>0</static>
    <plugin name='cmdvel_controller' filename='liballinonegazebo.so'>
      <robotNamespace>/all_in_one</robotNamespace>
    </plugin>
  </model>
</sdf>
